<?xml version="1.0" encoding="UTF-8"?>
<testsuites>
  <testsuite name="examples/all_features/all_features" errors="0" failures="63" tests="98">
    <testcase classname="examples/all_features/assertion_macros.cpp" name="normal macros" status="run">
      <failure type="CHECK">
examples/all_features/assertion_macros.cpp(0):
CHECK( throw_if(true, std::runtime_error("whops!")) == 42 ) THREW exception: "whops!"

      </failure>
      <failure message="Approx( 0.502 ) == 0.501" type="CHECK">
examples/all_features/assertion_macros.cpp(0):
CHECK( doctest::Approx(0.502) == 0.501 ) is NOT correct!
  values: CHECK( Approx( 0.502 ) == 0.501 )

      </failure>
    </testcase>
    <testcase classname="examples/all_features/assertion_macros.cpp" name="expressions should be evaluated only once" status="run"/>
    <testcase classname="examples/all_features/assertion_macros.cpp" name="exceptions-related macros" status="run">
      <failure type="CHECK_THROWS">
examples/all_features/assertion_macros.cpp(0):
CHECK_THROWS( throw_if(false, 0) ) did NOT throw at all!

      </failure>
      <failure type="CHECK_THROWS_AS">
examples/all_features/assertion_macros.cpp(0):
CHECK_THROWS_AS( throw_if(true, 0), char ) threw a DIFFERENT exception: "0"

      </failure>
      <failure type="CHECK_THROWS_AS">
examples/all_features/assertion_macros.cpp(0):
CHECK_THROWS_AS( throw_if(false, 0), int ) did NOT throw at all!

      </failure>
      <failure type="CHECK_THROWS_WITH">
examples/all_features/assertion_macros.cpp(0):
CHECK_THROWS_WITH( throw_if(true, "whops!"), "whops! no match!" ) threw a DIFFERENT exception: "whops!"

      </failure>
      <failure type="CHECK_THROWS_WITH">
examples/all_features/assertion_macros.cpp(0):
CHECK_THROWS_WITH( throw_if(true, "whops! does it match?"), "whops! no match!" ) threw a DIFFERENT exception: "whops! does it match?"

      </failure>
      <failure type="CHECK_THROWS_WITH_AS">
examples/all_features/assertion_macros.cpp(0):
CHECK_THROWS_WITH_AS( throw_if(true, "whops!"), "whops! no match!", bool ) threw a DIFFERENT exception! (contents: "whops!")

      </failure>
      <failure type="CHECK_THROWS_WITH_AS">
examples/all_features/assertion_macros.cpp(0):
CHECK_THROWS_WITH_AS( throw_if(true, "whops!"), "whops!", int ) threw a DIFFERENT exception! (contents: "whops!")

      </failure>
      <failure type="CHECK_THROWS_WITH_AS">
examples/all_features/assertion_macros.cpp(0):
CHECK_THROWS_WITH_AS( throw_if(true, "whops! does it match?"), "whops! no match!", int ) threw a DIFFERENT exception! (contents: "whops! does it match?")

      </failure>
      <failure type="CHECK_NOTHROW">
examples/all_features/assertion_macros.cpp(0):
CHECK_NOTHROW( throw_if(true, 0) ) THREW exception: "0"

      </failure>
    </testcase>
    <testcase classname="examples/all_features/assertion_macros.cpp" name="exceptions-related macros for std::exception" status="run">
      <failure type="CHECK_THROWS">
examples/all_features/assertion_macros.cpp(0):
CHECK_THROWS( throw_if(false, 0) ) did NOT throw at all!

      </failure>
      <failure type="CHECK_THROWS_AS">
examples/all_features/assertion_macros.cpp(0):
CHECK_THROWS_AS( throw_if(false, std::runtime_error("whops!")), std::exception ) did NOT throw at all!

      </failure>
      <failure type="CHECK_THROWS_AS">
examples/all_features/assertion_macros.cpp(0):
CHECK_THROWS_AS( throw_if(true, std::runtime_error("whops!")), int ) threw a DIFFERENT exception: "whops!"

      </failure>
      <failure type="CHECK_THROWS_WITH">
examples/all_features/assertion_macros.cpp(0):
CHECK_THROWS_WITH( throw_if(false, ""), "whops!" ) did NOT throw at all!

      </failure>
      <failure type="REQUIRE_NOTHROW">
examples/all_features/assertion_macros.cpp(0):
REQUIRE_NOTHROW( throw_if(true, std::runtime_error("whops!")) ) THREW exception: "whops!"

      </failure>
    </testcase>
    <testcase classname="examples/all_features/assertion_macros.cpp" name="WARN level of asserts don't fail the test case" status="run">
      <failure message="0" type="WARN">
examples/all_features/assertion_macros.cpp(0):
WARN( 0 ) is NOT correct!
  values: WARN( 0 )

      </failure>
      <failure message="1" type="WARN_FALSE">
examples/all_features/assertion_macros.cpp(0):
WARN_FALSE( 1 ) is NOT correct!
  values: WARN_FALSE( 1 )

      </failure>
      <failure type="WARN_THROWS">
examples/all_features/assertion_macros.cpp(0):
WARN_THROWS( throw_if(false, 0) ) did NOT throw at all!

      </failure>
      <failure type="WARN_THROWS_WITH">
examples/all_features/assertion_macros.cpp(0):
WARN_THROWS_WITH( throw_if(true, ""), "whops!" ) threw a DIFFERENT exception: 

      </failure>
      <failure type="WARN_THROWS_WITH">
examples/all_features/assertion_macros.cpp(0):
WARN_THROWS_WITH( throw_if(false, ""), "whops!" ) did NOT throw at all!

      </failure>
      <failure type="WARN_THROWS_AS">
examples/all_features/assertion_macros.cpp(0):
WARN_THROWS_AS( throw_if(false, 0), bool ) did NOT throw at all!

      </failure>
      <failure type="WARN_THROWS_AS">
examples/all_features/assertion_macros.cpp(0):
WARN_THROWS_AS( throw_if(true, 0), bool ) threw a DIFFERENT exception: "0"

      </failure>
      <failure type="WARN_THROWS_WITH_AS">
examples/all_features/assertion_macros.cpp(0):
WARN_THROWS_WITH_AS( throw_if(false, ""), "whops!", int ) did NOT throw at all!

      </failure>
      <failure type="WARN_THROWS_WITH_AS">
examples/all_features/assertion_macros.cpp(0):
WARN_THROWS_WITH_AS( throw_if(true, ""), "whops!", int ) threw a DIFFERENT exception! (contents: )

      </failure>
      <failure type="WARN_NOTHROW">
examples/all_features/assertion_macros.cpp(0):
WARN_NOTHROW( throw_if(true, 0) ) THREW exception: "0"

      </failure>
      <failure message="1, 0" type="WARN_EQ">
examples/all_features/assertion_macros.cpp(0):
WARN_EQ( 1, 0 ) is NOT correct!
  values: WARN_EQ( 1, 0 )

      </failure>
      <failure message="0" type="WARN_UNARY">
examples/all_features/assertion_macros.cpp(0):
WARN_UNARY( 0 ) is NOT correct!
  values: WARN_UNARY( 0 )

      </failure>
      <failure message="1" type="WARN_UNARY_FALSE">
examples/all_features/assertion_macros.cpp(0):
WARN_UNARY_FALSE( 1 ) is NOT correct!
  values: WARN_UNARY_FALSE( 1 )

      </failure>
    </testcase>
    <testcase classname="examples/all_features/assertion_macros.cpp" name="CHECK level of asserts fail the test case but don't abort it" status="run">
      <failure message="0" type="CHECK">
examples/all_features/assertion_macros.cpp(0):
CHECK( 0 ) is NOT correct!
  values: CHECK( 0 )

      </failure>
      <failure message="1" type="CHECK_FALSE">
examples/all_features/assertion_macros.cpp(0):
CHECK_FALSE( 1 ) is NOT correct!
  values: CHECK_FALSE( 1 )

      </failure>
      <failure type="CHECK_THROWS">
examples/all_features/assertion_macros.cpp(0):
CHECK_THROWS( throw_if(false, 0) ) did NOT throw at all!

      </failure>
      <failure type="CHECK_THROWS_AS">
examples/all_features/assertion_macros.cpp(0):
CHECK_THROWS_AS( throw_if(false, 0), bool ) did NOT throw at all!

      </failure>
      <failure type="CHECK_THROWS_AS">
examples/all_features/assertion_macros.cpp(0):
CHECK_THROWS_AS( throw_if(true, 0), bool ) threw a DIFFERENT exception: "0"

      </failure>
      <failure type="CHECK_THROWS_WITH">
examples/all_features/assertion_macros.cpp(0):
CHECK_THROWS_WITH( throw_if(true, 0), "unrecognized" ) threw a DIFFERENT exception: "0"

      </failure>
      <failure type="CHECK_THROWS_WITH_AS">
examples/all_features/assertion_macros.cpp(0):
CHECK_THROWS_WITH_AS( throw_if(true, 0), "unrecognized", int ) threw a DIFFERENT exception! (contents: "0")

      </failure>
      <failure type="CHECK_NOTHROW">
examples/all_features/assertion_macros.cpp(0):
CHECK_NOTHROW( throw_if(true, 0) ) THREW exception: "0"

      </failure>
      <failure message="1, 0" type="CHECK_EQ">
examples/all_features/assertion_macros.cpp(0):
CHECK_EQ( 1, 0 ) is NOT correct!
  values: CHECK_EQ( 1, 0 )

      </failure>
      <failure message="0" type="CHECK_UNARY">
examples/all_features/assertion_macros.cpp(0):
CHECK_UNARY( 0 ) is NOT correct!
  values: CHECK_UNARY( 0 )

      </failure>
      <failure message="1" type="CHECK_UNARY_FALSE">
examples/all_features/assertion_macros.cpp(0):
CHECK_UNARY_FALSE( 1 ) is NOT correct!
  values: CHECK_UNARY_FALSE( 1 )

      </failure>
    </testcase>
    <testcase classname="examples/all_features/assertion_macros.cpp" name="REQUIRE level of asserts fail and abort the test case - 1" status="run">
      <failure message="0" type="REQUIRE">
examples/all_features/assertion_macros.cpp(0):
REQUIRE( 0 ) is NOT correct!
  values: REQUIRE( 0 )

      </failure>
    </testcase>
    <testcase classname="examples/all_features/assertion_macros.cpp" name="REQUIRE level of asserts fail and abort the test case - 2" status="run">
      <failure message="1" type="REQUIRE_FALSE">
examples/all_features/assertion_macros.cpp(0):
REQUIRE_FALSE( 1 ) is NOT correct!
  values: REQUIRE_FALSE( 1 )

      </failure>
    </testcase>
    <testcase classname="examples/all_features/assertion_macros.cpp" name="REQUIRE level of asserts fail and abort the test case - 3" status="run">
      <failure type="REQUIRE_THROWS">
examples/all_features/assertion_macros.cpp(0):
REQUIRE_THROWS( throw_if(false, 0) ) did NOT throw at all!

      </failure>
    </testcase>
    <testcase classname="examples/all_features/assertion_macros.cpp" name="REQUIRE level of asserts fail and abort the test case - 4" status="run">
      <failure type="REQUIRE_THROWS_AS">
examples/all_features/assertion_macros.cpp(0):
REQUIRE_THROWS_AS( throw_if(false, 0), bool ) did NOT throw at all!

      </failure>
    </testcase>
    <testcase classname="examples/all_features/assertion_macros.cpp" name="REQUIRE level of asserts fail and abort the test case - 5" status="run">
      <failure type="REQUIRE_THROWS_AS">
examples/all_features/assertion_macros.cpp(0):
REQUIRE_THROWS_AS( throw_if(true, 0), bool ) threw a DIFFERENT exception: "0"

      </failure>
    </testcase>
    <testcase classname="examples/all_features/assertion_macros.cpp" name="REQUIRE level of asserts fail and abort the test case - 6" status="run">
      <failure type="REQUIRE_THROWS_WITH">
examples/all_features/assertion_macros.cpp(0):
REQUIRE_THROWS_WITH( throw_if(false, ""), "whops!" ) did NOT throw at all!

      </failure>
    </testcase>
    <testcase classname="examples/all_features/assertion_macros.cpp" name="REQUIRE level of asserts fail and abort the test case - 7" status="run">
      <failure type="REQUIRE_THROWS_WITH">
examples/all_features/assertion_macros.cpp(0):
REQUIRE_THROWS_WITH( throw_if(true, ""), "whops!" ) threw a DIFFERENT exception: 

      </failure>
    </testcase>
    <testcase classname="examples/all_features/assertion_macros.cpp" name="REQUIRE level of asserts fail and abort the test case - 8" status="run">
      <failure type="REQUIRE_THROWS_WITH_AS">
examples/all_features/assertion_macros.cpp(0):
REQUIRE_THROWS_WITH_AS( throw_if(false, ""), "whops!", bool ) did NOT throw at all!

      </failure>
    </testcase>
    <testcase classname="examples/all_features/assertion_macros.cpp" name="REQUIRE level of asserts fail and abort the test case - 9" status="run">
      <failure type="REQUIRE_THROWS_WITH_AS">
examples/all_features/assertion_macros.cpp(0):
REQUIRE_THROWS_WITH_AS( throw_if(true, ""), "whops!", bool ) threw a DIFFERENT exception! (contents: )

      </failure>
    </testcase>
    <testcase classname="examples/all_features/assertion_macros.cpp" name="REQUIRE level of asserts fail and abort the test case - 10" status="run">
      <failure type="REQUIRE_NOTHROW">
examples/all_features/assertion_macros.cpp(0):
REQUIRE_NOTHROW( throw_if(true, 0) ) THREW exception: "0"

      </failure>
    </testcase>
    <testcase classname="examples/all_features/assertion_macros.cpp" name="REQUIRE level of asserts fail and abort the test case - 11" status="run">
      <failure message="1, 0" type="REQUIRE_EQ">
examples/all_features/assertion_macros.cpp(0):
REQUIRE_EQ( 1, 0 ) is NOT correct!
  values: REQUIRE_EQ( 1, 0 )

      </failure>
    </testcase>
    <testcase classname="examples/all_features/assertion_macros.cpp" name="REQUIRE level of asserts fail and abort the test case - 12" status="run">
      <failure message="0" type="REQUIRE_UNARY">
examples/all_features/assertion_macros.cpp(0):
REQUIRE_UNARY( 0 ) is NOT correct!
  values: REQUIRE_UNARY( 0 )

      </failure>
    </testcase>
    <testcase classname="examples/all_features/assertion_macros.cpp" name="REQUIRE level of asserts fail and abort the test case - 13" status="run">
      <failure message="1" type="REQUIRE_UNARY_FALSE">
examples/all_features/assertion_macros.cpp(0):
REQUIRE_UNARY_FALSE( 1 ) is NOT correct!
  values: REQUIRE_UNARY_FALSE( 1 )

      </failure>
    </testcase>
    <testcase classname="examples/all_features/assertion_macros.cpp" name="all binary assertions" status="run"/>
    <testcase classname="examples/all_features/assertion_macros.cpp" name="some asserts used in a function called by a test case" status="run">
      <failure type="CHECK_THROWS_WITH_AS">
examples/all_features/assertion_macros.cpp(0):
CHECK_THROWS_WITH_AS( throw_if(true, false), "unknown exception", int ) threw a DIFFERENT exception! (contents: "unknown exception")

      </failure>
    </testcase>
    <testcase classname="examples/all_features/assertion_macros.cpp" name="check return values" status="run"/>
    <testcase classname="examples/all_features/assertion_macros.cpp" name="check return values no print" status="run">
      <failure message="4 == 2" type="CHECK">
examples/all_features/assertion_macros.cpp(0):
CHECK( a == b ) is NOT correct!
  values: CHECK( 4 == 2 )

      </failure>
      <failure message="4 != 2" type="CHECK_FALSE">
examples/all_features/assertion_macros.cpp(0):
CHECK_FALSE( a != b ) is NOT correct!
  values: CHECK_FALSE( 4 != 2 )

      </failure>
      <failure message="4, 2" type="CHECK_EQ">
examples/all_features/assertion_macros.cpp(0):
CHECK_EQ( a, b ) is NOT correct!
  values: CHECK_EQ( 4, 2 )

      </failure>
      <failure message="false" type="CHECK_UNARY">
examples/all_features/assertion_macros.cpp(0):
CHECK_UNARY( a == b ) is NOT correct!
  values: CHECK_UNARY( false )

      </failure>
      <failure message="true" type="CHECK_UNARY_FALSE">
examples/all_features/assertion_macros.cpp(0):
CHECK_UNARY_FALSE( a != b ) is NOT correct!
  values: CHECK_UNARY_FALSE( true )

      </failure>
      <failure type="CHECK_THROWS">
examples/all_features/assertion_macros.cpp(0):
CHECK_THROWS( throw_if(false, false) ) did NOT throw at all!

      </failure>
      <failure type="CHECK_THROWS_AS">
examples/all_features/assertion_macros.cpp(0):
CHECK_THROWS_AS( throw_if(true, 2), doctest::Approx ) threw a DIFFERENT exception: "2"

      </failure>
      <failure type="CHECK_NOTHROW">
examples/all_features/assertion_macros.cpp(0):
CHECK_NOTHROW( throw_if(true, 2) ) THREW exception: "2"

      </failure>
      <failure type="CHECK_THROWS_WITH">
examples/all_features/assertion_macros.cpp(0):
CHECK_THROWS_WITH( throw_if(true, 2), "1" ) threw a DIFFERENT exception: "2"

      </failure>
    </testcase>
  </testsuite>
</testsuites>
Program code.
